Workbook

Sheet Audit information
A1: AUDIT INFORMATION | B1: UPDATE THIS COLUMN | D1: SPECIAL INSTRUCTIONS: | H1: KEY | I1: THIS COLUMN SHOULD NOT NEED TO BE UPDATED | T1: DO NOT CHANGE THESE
A2: Auditee | B2: <<Auditee>> | H2: Yes | T2: ,
A3: Audit duration | B3: ## | C3: <- | D3: NUMBER OF DAYS | H3: No | T3: ,
A4: Audit start date | B4: DD/MM/YYYY | D4: IF A CELL IN SUBSEQUENT SHEETS IS HIGHLIGHTED IN ORANGE, UPDATE INFORMATION IN THIS SHEET IF A CELL IN SUBSEQUENT SHEETS IS HIGHLIGHTED IN RED, UPDATE INFORMATION IN THAT SHEET | H4: N/A | T4: ,
A5: Audit end date | B5: =B4+(B3-1) -> #VALUE! | T5: , and
A6: Key auditee contact | B6: <<auditee contact>> | H6: TEXT FIELDS | T6: and
A7: Audit body | B7: <<Audit body>> | H7: No critical findings were identified during this document review.
A8: Lead auditor | B8: <<Lead auditor>> | F8: If you need to update this text, use cells E9 and F9 | G8: -> | H8: =CONCATENATE(J8,$B$2,K8) -> Based on information reviewed during the document review, the following items are deemed as being of critical significance within <<Auditee>>'s management system: | J8: Based on information reviewed during the document review, the following items are deemed as being of critical significance within | K8: 's management system:
A9: Number of audit team members | B9: # | C9: <- | D9: EXCLUDING LEAD AUDITOR | H9: No non-critical findings were identified during this document review.
A10: Team member 1 | B10: <<Team member 1>> | F10: If you need to update this text, use cells E11 and F11 | G10: -> | H10: =CONCATENATE(J10,$B$2,K10) -> Based on information reviewed during the document review, it is not clear how <<Auditee>> define or control the following: | J10: Based on information reviewed during the document review, it is not clear how | K10: define or control the following:
A11: Team member 2 | B11: <<Team member 2>> | H11: No major nonconformances were identified during this audit.
A12: Team member 3 | B12: <<Team member 3>> | H12: No minor nonconformances were identified during this audit.
A13: Team member 4 | B13: <<Team member 4>> | F13: If you need to update this text, use cells E14 and F14 | G13: -> | H13: =CONCATENATE(J13,$B$2,K13) -> In order to prevent potential future nonconformaces, it may be of benefit for <<Auditee>> to consider the following: | J13: In order to prevent potential future nonconformaces, it may be of benefit for | K13: to consider the following:
A14: Team member 5 | B14: <<Team member 5>> | H14: Based on information reviewed and processes observed at the time of audit, the audit team wish to highlight the following positive findings:
A15: Audit objective | B15: To determine the capablity of the management system to meet the audit criteria, and to identify areas of potential improvement. | F15: If you need to update this text, use cells E16 and F16 | G15: -> | H15: =CONCATENATE(J15,B7,K15) -> Thank you for selecting <<Audit body>> for the provision of audit services. Please refer to the following information regarding your audit. | J15: Thank you for selecting | K15: for the provision of audit services. Please refer to the following information regarding your audit.
A16: Audit scope | B16: <<Audit scope>> | F16: If you need to update this text, use cells E17 and F17 | G16: -> | H16: =CONCATENATE(J16,B7,K16) -> Thank you for selecting <<Audit body>> for the provision of audit services. Please refer to the following information regarding the outcome of your audit. | J16: Thank you for selecting | K16: for the provision of audit services. Please refer to the following information regarding the outcome of your audit.
A17: Audit criteria | B17: <<Audit criteria>> | H17: The audit will proceed once critical findings are sufficiently addressed.
A18: Audit client | B18: <<Audit client>> | F18: If you need to update this text, use cells E19 and F19 | G18: -> | H18: =CONCATENATE(J18,B34,K18) -> Major nonconformances were identified during this audit and will need to be corrected and verified within 90 days of the date of this report. | J18: Major nonconformances were identified during this audit and will need to be corrected and verified within | K18: of the date of this report.
A19: Main location | B19: <<Main location>> | F19: If you need to update this text, use cells E20 and F20 | G19: -> | H19: =CONCATENATE(J19,B34,K19) -> at a follow up audit within 90 days of this report. | J19: at a follow up audit within | K19: of this report.
A20: Number of other locations | B20: ## | C20: <- | D20: If uncertain of other sites, enter "1" here, and
A21: Location 1 | B21: <<Location 1>> | C21: <- | D21: "To be confirmed" here | H21: NC NUMBERING CONVENTION
A22: Location 2 | B22: <<Location 2>> | H22: NC01
A23: Location 3 | B23: <<Location 3>> | H23: NC02
A24: Location 4 | B24: <<Location 4>> | H24: NC03
A25: Location 5 | B25: <<Location 5>> | H25: NC04
H26: NC05
A27: DOCUMENT REVIEW | H27: NC06
A28: Documentation reviewed | B28: <<Document name>> | H28: NC07
A29: # of critical findings | B29: ## | H29: NC08
A30: # of non-critical findings | B30: ## | H30: NC09
H31: NC10
A32: AUDIT FINDINGS | H32: NC11
A33: # of major NC's | B33: ## | H33: NC12
A34: Major NC follow up time | B34: 90 days | C34: <- | D34: Change if required, 90 days is standard | H34: NC13
A35: Onsite follow up? | C35: <- | D35: Yes/No, or blank if no major NCs | H35: NC14
A36: # of minor NC's | B36: ## | H36: NC15
A37: Observations | C37: <- | D37: Yes/No | H37: NC16
A38: Positive findings | C38: <- | D38: Yes/No | H38: NC17
H39: NC18
H40: NC19
...

Sheet Document review report
A1: Document Review Report
A3: Organisation to be audited: | B3: ='Audit information'!B2 -> <<Auditee>>
A4: Prepared by: | B4: ='Audit information'!B8 -> <<Lead auditor>>
A5: Audit client: | B5: ='Audit information'!B18 -> <<Audit client>>
A7: Audit objective: | B7: ='Audit information'!B15 -> To determine the capablity of the management system to meet the audit criteria, and to identify areas of potential improvement.
A8: Audit scope: | B8: ='Audit information'!B16 -> <<Audit scope>>
A9: Audit criteria: | B9: ='Audit information'!B17 -> <<Audit criteria>>
A11: Documentation reviewed: | B11: ='Audit information'!B28 -> <<Document name>>
A12: =IF('Audit information'!$B$9=0,"Principal auditor:","Lead auditor:") -> Lead auditor: | B12: ='Audit information'!B8 -> <<Lead auditor>>
A13: Audit team members: | B13: =IF('Audit information'!B9=0,"Nil",(IF('Audit information'!B9=1,'Audit information'!B10,(IF('Audit information'!B9=2,(CONCATENATE('Audit information'!B10,'Audit information'!T6,'Audit information'!B11)),(IF('Audit information'!B9=3,(CONCATENATE('Audit information'!B10,'Audit information'!T4,'Audit information'!B11,'Audit information'!T5,'Audit information'!B12)),(IF('Audit information'!B9=4,(CONCATENATE('Audit information'!B10,'Audit information'!T3,'Audit information'!B11,'Audit information'!T4,'Audit information'!B12,'Audit information'!T5,'Audit information'!B13)),(IF('Audit information'!B9=5,(CONCATENATE('Audit information'!B10,'Audit information'!T2,'Audit information'!B11,'Audit information'!T3,'Audit information'!B12,'Audit information'!T4,'Audit information'!B13,'Audit information'!T5,'Audit information'!B14))))))))))))) -> FALSE
A15: Main audit location: | B15: ='Audit information'!B19 -> <<Main location>>
A16: Other location/s: | B16: =IF('Audit information'!B20=0,"Nil",(IF('Audit information'!B20=1,'Audit information'!B21,(IF('Audit information'!B20=2,(CONCATENATE('Audit information'!B21,'Audit information'!T6,'Audit information'!B22)),(IF('Audit information'!B20=3,(CONCATENATE('Audit information'!B21,'Audit information'!T4,'Audit information'!B22,'Audit information'!T5,'Audit information'!B23)),(IF('Audit information'!B20=4,(CONCATENATE('Audit information'!B21,'Audit information'!T3,'Audit information'!B22,'Audit information'!T4,'Audit information'!B23,'Audit information'!T5,'Audit information'!B24)),(IF('Audit information'!B20=5,(CONCATENATE('Audit information'!B21,'Audit information'!T2,'Audit information'!B22,'Audit information'!T3,'Audit information'!B23,'Audit information'!T4,'Audit information'!B24,'Audit information'!T5,'Audit information'!B25))))))))))))) -> FALSE
A17: Distribution list: | B17: ='Audit information'!B6 -> <<auditee contact>>
A19: Documentation review risks & results:
A20: Audit objective, scope and criteria are appropriate based on the document review.
A21: The time allowed for the document review was sufficient.
A22: The audit team, including any technical experts, has the required competence.
A23: Critical findings were identified during this document review and these will need to be corrected and verified before the site audit can commence. | C23: =IF('Audit information'!B29>0,'Audit information'!H2,'Audit information'!H3) -> Yes
A24: Non-critical findings were identified during this audit and failure to correct these may result in nonconformances at the site audit. | C24: =IF('Audit information'!B30>0,'Audit information'!H2,'Audit information'!H3) -> Yes
A25: The site audit should proceed as planned. | C25: =IF(C23='Audit information'!H2,'Audit information'!H3,'Audit information'!H2) -> No
A26: Planned commencement date: | B26: =IF(C25='Audit information'!H2,'Audit information'!B4,'Audit information'!H17) -> The audit will proceed once critical findings are sufficiently addressed.
A28: Actions to address any shortcomings:
A29: - Refer to attached document review findings.
A30: Signed:
A31: Date: | B31: DD/MM/YYYY

Sheet Doc review findings
A1: Document Review Findings
A3: Critical findings
A5: =IF('Audit information'!B29=0,'Audit information'!H7,'Audit information'!H8) -> Based on information reviewed during the document review, the following items are deemed as being of critical significance within <<Auditee>>'s management system:
A10: Non-critical findings
A12: =IF('Audit information'!B30=0,'Audit information'!H9,'Audit information'!H10) -> Based on information reviewed during the document review, it is not clear how <<Auditee>> define or control the following:

Sheet Audit plan
A1: Audit Plan
A3: ='Audit information'!H15 -> Thank you for selecting <<Audit body>> for the provision of audit services. Please refer to the following information regarding your audit.
A5: Organisation to be audited: | B5: ='Audit information'!B2 -> <<Auditee>>
A6: Client requesting audit: | B6: ='Audit information'!B18 -> <<Audit client>>
A7: Audit objective: | B7: ='Audit information'!B15 -> To determine the capablity of the management system to meet the audit criteria, and to identify areas of potential improvement.
A8: Audit scope: | B8: ='Audit information'!B16 -> <<Audit scope>>
A9: Audit criteria: | B9: ='Audit information'!B17 -> <<Audit criteria>>
A10: =IF('Audit information'!B3=1,"Audit date:","Audit dates:") -> Audit dates: | B10: =IFERROR(IF('Audit information'!B3=1,TEXT('Audit information'!B4,"DD/MM/YYYY"),(TEXT('Audit information'!B4,"DD/MM/YYYY")&" to "&(TEXT('Audit information'!B5,"DD/MM/YYYY")))),"<<Audit date>>") -> <<Audit date>>
B11: For a breakdown of audit activities, refer to attached audit timetable.
A12: Main audit location: | B12: ='Audit information'!B19 -> <<Main location>>
A13: Other locations: | B13: =IF('Audit information'!B20=0,"Nil",(IF('Audit information'!B20=1,'Audit information'!B21,(IF('Audit information'!B20=2,(CONCATENATE('Audit information'!B21,'Audit information'!T6,'Audit information'!B22)),(IF('Audit information'!B20=3,(CONCATENATE('Audit information'!B21,'Audit information'!T4,'Audit information'!B22,'Audit information'!T5,'Audit information'!B23)),(IF('Audit information'!B20=4,(CONCATENATE('Audit information'!B21,'Audit information'!T3,'Audit information'!B22,'Audit information'!T4,'Audit information'!B23,'Audit information'!T5,'Audit information'!B24)),(IF('Audit information'!B20=5,(CONCATENATE('Audit information'!B21,'Audit information'!T2,'Audit information'!B22,'Audit information'!T3,'Audit information'!B23,'Audit information'!T4,'Audit information'!B24,'Audit information'!T5,'Audit information'!B25))))))))))))) -> FALSE
A14: =IF('Audit information'!$B$9=0,"Principal auditor:","Lead auditor:") -> Lead auditor: | B14: ='Audit information'!B8 -> <<Lead auditor>>
A15: Audit team members: | B15: =IF('Audit information'!B9=0,"Nil",(IF('Audit information'!B9=1,'Audit information'!B10,(IF('Audit information'!B9=2,(CONCATENATE('Audit information'!B10,'Audit information'!T6,'Audit information'!B11)),(IF('Audit information'!B9=3,(CONCATENATE('Audit information'!B10,'Audit information'!T4,'Audit information'!B11,'Audit information'!T5,'Audit information'!B12)),(IF('Audit information'!B9=4,(CONCATENATE('Audit information'!B10,'Audit information'!T3,'Audit information'!B11,'Audit information'!T4,'Audit information'!B12,'Audit information'!T5,'Audit information'!B13)),(IF('Audit information'!B9=5,(CONCATENATE('Audit information'!B10,'Audit information'!T2,'Audit information'!B11,'Audit information'!T3,'Audit information'!B12,'Audit information'!T4,'Audit information'!B13,'Audit information'!T5,'Audit information'!B14))))))))))))) -> FALSE
A16: Auditee contact: | B16: ='Audit information'!B6 -> <<auditee contact>>
A18: Logistic and resource requirements:
A19: Meeting room; quiet working room (can be same as meeting room); lunch
A20: Other requirements: | B20: =IF(A21="<<PPE; induction requirements; environmental concerns; cultural, religious, social, or dress requirements>>","UPDATE BELOW FIELD","") -> UPDATE BELOW FIELD
A21: <<PPE; induction requirements; environmental concerns; cultural, religious, social, or dress requirements>>
A22: Signed:
A23: Date: | B23: DD/MM/YYYY
A25: Please note: An audit is based on a sample of an organisation's management system and processes. Therefore, any audit findings are indicative of performance, however may not be reflected in the organisation's broader operations. It is possible that other nonconformances may be present within the organisation at the time of audit, however won't be uncovered due to the sample taken.
A27: All information and documentation collected during the audit will be held in the highest confidence.

Sheet Audit timetable (team)
A1: =IF('Audit information'!B9>0,(IF('Audit information'!B3=1,"Audit Timetable","Audit Timetable - Day 1")),"USE OTHER AUDIT TIMETABLE TEMPLATE") -> Audit Timetable - Day 1
D2: Audit date: | E2: ='Audit information'!$B$4 -> DD/MM/YYYY | G2: Audit date: | H2: ='Audit information'!$B$4 -> DD/MM/YYYY | L2: Audit date: | M2: ='Audit information'!$B$4 -> DD/MM/YYYY
B3: Lead auditor: | C3: ='Audit information'!$B$8 -> <<Lead auditor>> | D3: Team member: | E3: =IF('Audit information'!$B$9>0,'Audit information'!$B$10,"USE OTHER TIMETABLE TEMPLATE") -> <<Team member 1>> | G3: =IF('Audit information'!$B$9>1,"Team member:","DELETE COLUMN") -> Team member: | H3: =IF('Audit information'!$B$9>1,'Audit information'!$B$11,"DELETE COLUMN") -> <<Team member 2>> | I3: =IF('Audit information'!$B$9>2,"Team member:","DELETE COLUMN") -> Team member: | J3: =IF('Audit information'!$B$9>2,'Audit information'!$B$12,"DELETE COLUMN") -> <<Team member 3>> | L3: =IF('Audit information'!$B$9>3,"Team member:","DELETE COLUMN") -> Team member: | M3: =IF('Audit information'!$B$9>3,'Audit information'!$B$13,"DELETE COLUMN") -> <<Team member 4>> | N3: =IF('Audit information'!$B$9>4,"Team member:","DELETE COLUMN") -> Team member: | O3: =IF('Audit information'!$B$9>4,'Audit information'!$B$14,"DELETE COLUMN") -> <<Team member 5>>
B4: Audit activity | C4: Location | D4: Audit activity | E4: Location | G4: Audit activity | H4: Location | I4: Audit activity | J4: Location | L4: Audit activity | M4: Location | N4: Audit activity | O4: Location
A5: 0.33333333 | F5: 0.33333333 | K5: 0.33333333
A6: 0.35416667 | F6: 0.35416667 | K6: 0.35416667
A7: 0.375 | F7: 0.375 | K7: 0.375
A8: 0.39583333 | F8: 0.39583333 | K8: 0.39583333
A9: 0.41666667 | F9: 0.41666667 | K9: 0.41666667
A10: 0.4375 | F10: 0.4375 | K10: 0.4375
A11: 0.45833333 | F11: 0.45833333 | K11: 0.45833333
A12: 0.47916667 | F12: 0.47916667 | K12: 0.47916667
A13: 0.5 | F13: 0.5 | K13: 0.5
A14: 0.52083333 | F14: 0.52083333 | K14: 0.52083333
A15: 0.54166667 | F15: 0.54166667 | K15: 0.54166667
A16: 0.5625 | F16: 0.5625 | K16: 0.5625
... A23: 0.70833333 | F23: 0.70833333 | K23: 0.70833333
A35: =IF('Audit information'!$B$3>1,"Audit Timetable - Day 2","DELETE TABLE") -> Audit Timetable - Day 2
D36: Audit date: | E36: =IF('Audit information'!$B$3>1,'Audit information'!$B$4+1,"DELETE TABLE") -> #VALUE! | G36: Audit date: | H36: =IF('Audit information'!$B$3>1,'Audit information'!$B$4+1,"DELETE TABLE") -> #VALUE! | L36: Audit date: | M36: =IF('Audit information'!$B$3>1,'Audit information'!$B$4+1,"DELETE TABLE") -> #VALUE!
B37: Lead auditor: | C37: ='Audit information'!$B$8 -> <<Lead auditor>> | D37: Team member: | E37: ='Audit information'!$B$10 -> <<Team member 1>> | G37: =IF('Audit information'!$B$9>1,"Team member:","DELETE COLUMN") -> Team member: | H37: =IF('Audit information'!$B$9>1,'Audit information'!$B$11,"DELETE COLUMN") -> <<Team member 2>> | I37: =IF('Audit information'!$B$9>2,"Team member:","DELETE COLUMN") -> Team member: | J37: =IF('Audit information'!$B$9>2,'Audit information'!$B$12,"DELETE COLUMN") -> <<Team member 3>> | L37: =IF('Audit information'!$B$9>3,"Team member:","DELETE COLUMN") -> Team member: | M37: =IF('Audit information'!$B$9>3,'Audit information'!$B$13,"DELETE COLUMN") -> <<Team member 4>> | N37: =IF('Audit information'!$B$9>4,"Team member:","DELETE COLUMN") -> Team member: | O37: =IF('Audit information'!$B$9>4,'Audit information'!$B$14,"DELETE COLUMN") -> <<Team member 5>>
B38: Audit activity | C38: Location | D38: Audit activity | E38: Location | G38: Audit activity | H38: Location | I38: Audit activity | J38: Location | L38: Audit activity | M38: Location | N38: Audit activity | O38: Location
A39: 0.33333333 | F39: 0.33333333 | K39: 0.33333333
A40: 0.35416667 | F40: 0.35416667 | K40: 0.35416667
A41: 0.375 | F41: 0.375 | K41: 0.375
A42: 0.39583333 | F42: 0.39583333 | K42: 0.39583333
A43: 0.41666667 | F43: 0.41666667 | K43: 0.41666667
A44: 0.4375 | F44: 0.4375 | K44: 0.4375
A45: 0.45833333 | F45: 0.45833333 | K45: 0.45833333
A46: 0.47916667 | F46: 0.47916667 | K46: 0.47916667
A47: 0.5 | F47: 0.5 | K47: 0.5
A48: 0.52083333 | F48: 0.52083333 | K48: 0.52083333
A49: 0.54166667 | F49: 0.54166667 | K49: 0.54166667
A50: 0.5625 | F50: 0.5625 | K50: 0.5625
... A57: 0.70833333 | F57: 0.70833333 | K57: 0.70833333
A69: =IF('Audit information'!$B$3>2,"Audit Timetable - Day 3","DELETE TABLE") -> Audit Timetable - Day 3
D70: Audit date: | E70: =IF('Audit information'!$B$3>2,'Audit information'!$B$4+2,"DELETE TABLE") -> #VALUE! | G70: Audit date: | H70: =IF('Audit information'!$B$3>2,'Audit information'!$B$4+2,"DELETE TABLE") -> #VALUE! | L70: Audit date: | M70: =IF('Audit information'!$B$3>2,'Audit information'!$B$4+2,"DELETE TABLE") -> #VALUE!
B71: Lead auditor: | C71: ='Audit information'!$B$8 -> <<Lead auditor>> | D71: Team member: | E71: ='Audit information'!$B$10 -> <<Team member 1>> | G71: =IF('Audit information'!$B$9>1,"Team member:","DELETE COLUMN") -> Team member: | H71: =IF('Audit information'!$B$9>1,'Audit information'!$B$11,"DELETE COLUMN") -> <<Team member 2>> | I71: =IF('Audit information'!$B$9>2,"Team member:","DELETE COLUMN") -> Team member: | J71: =IF('Audit information'!$B$9>2,'Audit information'!$B$12,"DELETE COLUMN") -> <<Team member 3>> | L71: =IF('Audit information'!$B$9>3,"Team member:","DELETE COLUMN") -> Team member: | M71: =IF('Audit information'!$B$9>3,'Audit information'!$B$13,"DELETE COLUMN") -> <<Team member 4>> | N71: =IF('Audit information'!$B$9>4,"Team member:","DELETE COLUMN") -> Team member: | O71: =IF('Audit information'!$B$9>4,'Audit information'!$B$14,"DELETE COLUMN") -> <<Team member 5>>
B72: Audit activity | C72: Location | D72: Audit activity | E72: Location | G72: Audit activity | H72: Location | I72: Audit activity | J72: Location | L72: Audit activity | M72: Location | N72: Audit activity | O72: Location
A73: 0.33333333 | F73: 0.33333333 | K73: 0.33333333
A74: 0.35416667 | F74: 0.35416667 | K74: 0.35416667
...

Sheet Audit timetable (principal)
A1: =IF('Audit information'!B9=0,(IF('Audit information'!B3=1,"Audit Timetable","Audit Timetable - Day 1")),"USE OTHER AUDIT TIMETABLE TEMPLATE") -> USE OTHER AUDIT TIMETABLE TEMPLATE
D2: Audit date: | E2: ='Audit information'!B4 -> DD/MM/YYYY
B3: Principal auditor: | C3: ='Audit information'!$B$8 -> <<Lead auditor>>
B4: Audit activity | E4: Location
A5: 0.33333333
A6: 0.35416667
A7: 0.375
A8: 0.39583333
A9: 0.41666667
A10: 0.4375
A11: 0.45833333
A12: 0.47916667
A13: 0.5
A14: 0.52083333
A15: 0.54166667
A16: 0.5625
... A23: 0.70833333
A35: =IF('Audit information'!$B$3>1,"Audit Timetable - Day 2","DELETE TABLE") -> Audit Timetable - Day 2
D36: Audit date: | E36: =IF('Audit information'!$B$3>1,'Audit information'!$B$4+1,"DELETE TABLE") -> #VALUE!
B37: Principal auditor: | C37: ='Audit information'!$B$8 -> <<Lead auditor>>
B38: Audit activity | E38: Location
A39: 0.33333333
A40: 0.35416667
A41: 0.375
A42: 0.39583333
A43: 0.41666667
A44: 0.4375
A45: 0.45833333
A46: 0.47916667
A47: 0.5
A48: 0.52083333
A49: 0.54166667
A50: 0.5625
... A57: 0.70833333
A69: =IF('Audit information'!$B$3>2,"Audit Timetable - Day 3","DELETE TABLE") -> Audit Timetable - Day 3
D70: Audit date: | E70: =IF('Audit information'!$B$3>2,'Audit information'!$B$4+2,"DELETE TABLE") -> #VALUE!
B71: Principal auditor: | C71: ='Audit information'!$B$8 -> <<Lead auditor>>
B72: Audit activity | E72: Location
A73: 0.33333333
A74: 0.35416667
...

Sheet Audit Report
A1: Audit Report
A3: ='Audit information'!H16 -> Thank you for selecting <<Audit body>> for the provision of audit services. Please refer to the following information regarding the outcome of your audit.
A5: Organisation audited: | B5: ='Audit information'!B2 -> <<Auditee>>
A6: Client requesting audit: | B6: ='Audit information'!B18 -> <<Audit client>>
A7: Report prepared by: | B7: ='Audit information'!B8 -> <<Lead auditor>>
A9: Audit objective: | B9: ='Audit information'!B15 -> To determine the capablity of the management system to meet the audit criteria, and to identify areas of potential improvement.
A10: Audit scope: | B10: ='Audit information'!B16 -> <<Audit scope>>
A11: Audit criteria: | B11: ='Audit information'!B17 -> <<Audit criteria>>
A12: =IF('Audit information'!B3=1,"Audit date:","Audit dates:") -> Audit dates: | B12: =IFERROR(IF('Audit information'!B3=1,TEXT('Audit information'!B4,"DD/MM/YYYY"),(TEXT('Audit information'!B4,"DD/MM/YYYY")&" to "&TEXT('Audit information'!B5,"DD/MM/YYYY"))),"<<Audit date>>") -> <<Audit date>>
A13: Main audit location: | B13: ='Audit information'!B19 -> <<Main location>>
A14: Other locations: | B14: =IF('Audit information'!B20=0,"Nil",(IF('Audit information'!B20=1,'Audit information'!B21,(IF('Audit information'!B20=2,(CONCATENATE('Audit information'!B21,'Audit information'!T6,'Audit information'!B22)),(IF('Audit information'!B20=3,(CONCATENATE('Audit information'!B21,'Audit information'!T4,'Audit information'!B22,'Audit information'!T5,'Audit information'!B23)),(IF('Audit information'!B20=4,(CONCATENATE('Audit information'!B21,'Audit information'!T3,'Audit information'!B22,'Audit information'!T4,'Audit information'!B23,'Audit information'!T5,'Audit information'!B24)),(IF('Audit information'!B20=5,(CONCATENATE('Audit information'!B21,'Audit information'!T2,'Audit information'!B22,'Audit information'!T3,'Audit information'!B23,'Audit information'!T4,'Audit information'!B24,'Audit information'!T5,'Audit information'!B25))))))))))))) -> FALSE
A15: =IF('Audit information'!$B$9=0,"Principal auditor:","Lead auditor:") -> Lead auditor: | B15: ='Audit information'!B8 -> <<Lead auditor>>
A16: Audit team members: | B16: =IF('Audit information'!B9=0,"Nil",(IF('Audit information'!B9=1,'Audit information'!B10,(IF('Audit information'!B9=2,(CONCATENATE('Audit information'!B10,'Audit information'!T6,'Audit information'!B11)),(IF('Audit information'!B9=3,(CONCATENATE('Audit information'!B10,'Audit information'!T4,'Audit information'!B11,'Audit information'!T5,'Audit information'!B12)),(IF('Audit information'!B9=4,(CONCATENATE('Audit information'!B10,'Audit information'!T3,'Audit information'!B11,'Audit information'!T4,'Audit information'!B12,'Audit information'!T5,'Audit information'!B13)),(IF('Audit information'!B9=5,(CONCATENATE('Audit information'!B10,'Audit information'!T2,'Audit information'!B11,'Audit information'!T3,'Audit information'!B12,'Audit information'!T4,'Audit information'!B13,'Audit information'!T5,'Audit information'!B14))))))))))))) -> FALSE
A17: Auditee contact: | B17: ='Audit information'!B6 -> <<auditee contact>>
A19: Audit Summary | B19: For details, please refer to attached audit findings
A20: ='Audit information'!H18 -> Major nonconformances were identified during this audit and will need to be corrected and verified within 90 days of the date of this report. | C20: =IF('Audit information'!B33>0,'Audit information'!H2,'Audit information'!H3) -> Yes
A21: Your actions will be verified: | B21: by you submitting appropriate evidence. | C21: =IF($C$20='Audit information'!$H$2,(IF('Audit information'!$B$35='Audit information'!$H$2,'Audit information'!$H$3,'Audit information'!$H$2)),'Audit information'!$H$4) -> Yes
B22: ='Audit information'!H19 -> at a follow up audit within 90 days of this report. | C22: =IF($C$20='Audit information'!$H$2,(IF('Audit information'!$B$35='Audit information'!$H$2,'Audit information'!$H$2,'Audit information'!$H$3)),'Audit information'!$H$4) -> No
A23: Minor nonconformances were identified during this audit and your actions will be verified at your next scheduled audit. | C23: =IF('Audit information'!$B$36>0,'Audit information'!$H$2,'Audit information'!$H$3) -> Yes
A25: Signed:
A26: Date: | B26: DD/MM/YYYY
A28: Please note: This audit was based on a sample of the organisation's management system and processes. Therefore, any audit findings are indicative of performance, however may not be reflected in the organisation's broader operations. It is possible that other nonconformances were present within the organisation at the time of audit, however weren't uncovered due to the sample taken.
A30: All information and documentation collected during the audit has be held in the highest confidence.

Sheet Audit findings
A1: Audit Findings
A3: Major nonconformances
A5: =IF('Audit information'!$B$33>0,'Audit information'!H22,'Audit information'!$H$11) -> NC01
A6: =IF('Audit information'!$B$33>0,"<<Requirement>>","") -> <<Requirement>>
A7: =IF('Audit information'!$B$33>0,"<<Evidence>>","DELETE ROW") -> <<Evidence>>
A8: =IF(A7="DELETE ROW","DELETE ROW","")
A9: =IF('Audit information'!$B$33>1,'Audit information'!H23,"DELETE ROW") -> NC02
A10: =IF('Audit information'!$B$33>1,"<<Requirement>>","DELETE ROW") -> <<Requirement>>
A11: =IF('Audit information'!$B$33>1,"<<Evidence>>","DELETE ROW") -> <<Evidence>>
A12: =IF(A11="DELETE ROW","DELETE ROW","")
A13: =IF('Audit information'!$B$33>2,'Audit information'!H24,"DELETE ROW") -> NC03
A14: =IF('Audit information'!$B$33>2,"<<Requirement>>","DELETE ROW") -> <<Requirement>>
A15: =IF('Audit information'!$B$33>2,"<<Evidence>>","DELETE ROW") -> <<Evidence>>
A16: =IF(A15="DELETE ROW","DELETE ROW","")
A17: =IF('Audit information'!$B$33>3,'Audit information'!H25,"DELETE ROW") -> NC04
A18: =IF('Audit information'!$B$33>3,"<<Requirement>>","DELETE ROW") -> <<Requirement>>
A19: =IF('Audit information'!$B$33>3,"<<Evidence>>","DELETE ROW") -> <<Evidence>>
A20: =IF(A19="DELETE ROW","DELETE ROW","")
A21: =IF('Audit information'!$B$33>4,'Audit information'!H26,"DELETE ROW") -> NC05
A22: =IF('Audit information'!$B$33>4,"<<Requirement>>","DELETE ROW") -> <<Requirement>>
A23: =IF('Audit information'!$B$33>4,"<<Evidence>>","DELETE ROW") -> <<Evidence>>
A24: =IF(A23="DELETE ROW","DELETE ROW","")
A25: Minor nonconformances
A27: =IF('Audit information'!$B$36>0,(IF('Audit information'!$B$33=0,'Audit information'!$H$22,(IF('Audit information'!$B$33=1,'Audit information'!$H$23,(IF('Audit information'!$B$33=2,'Audit information'!$H$24,(IF('Audit information'!$B$33=3,'Audit information'!$H$25,(IF('Audit information'!$B$33=4,'Audit information'!$H$26,(IF('Audit information'!$B$33=5,'Audit information'!$H$27,"NCXX")))))))))))),'Audit information'!$H$12) -> NCXX
A28: =IF('Audit information'!$B$36>0,"<<Requirement>>","DELETE ROW") -> <<Requirement>>
A29: =IF('Audit information'!$B$36>0,"<<Evidence>>","DELETE ROW") -> <<Evidence>>
A30: =IF(A29="DELETE ROW","DELETE ROW","")
A31: =IF('Audit information'!$B$36>1,(IF('Audit information'!$B$33=0,'Audit information'!$H$23,(IF('Audit information'!$B$33=1,'Audit information'!$H$24,(IF('Audit information'!$B$33=2,'Audit information'!$H$25,(IF('Audit information'!$B$33=3,'Audit information'!$H$26,(IF('Audit information'!$B$33=4,'Audit information'!$H$27,(IF('Audit information'!$B$33=5,'Audit information'!$H$28,"NCXX")))))))))))),"DELETE ROW") -> NCXX
A32: =IF('Audit information'!$B$36>1,"<<Requirement>>","DELETE ROW") -> <<Requirement>>
A33: =IF('Audit information'!$B$36>1,"<<Evidence>>","DELETE ROW") -> <<Evidence>>
A34: =IF(A33="DELETE ROW","DELETE ROW","")
A35: =IF('Audit information'!$B$36>2,(IF('Audit information'!$B$33=0,'Audit information'!$H$24,(IF('Audit information'!$B$33=1,'Audit information'!$H$25,(IF('Audit information'!$B$33=2,'Audit information'!$H$26,(IF('Audit information'!$B$33=3,'Audit information'!$H$27,(IF('Audit information'!$B$33=4,'Audit information'!$H$28,(IF('Audit information'!$B$33=5,'Audit information'!$H$29,"NCXX")))))))))))),"DELETE ROW") -> NCXX
A36: =IF('Audit information'!$B$36>2,"<<Requirement>>","DELETE ROW") -> <<Requirement>>
A37: =IF('Audit information'!$B$36>2,"<<Evidence>>","DELETE ROW") -> <<Evidence>>
A38: =IF(A37="DELETE ROW","DELETE ROW","")
A39: =IF('Audit information'!$B$36>3,(IF('Audit information'!$B$33=0,'Audit information'!$H$25,(IF('Audit information'!$B$33=1,'Audit information'!$H$26,(IF('Audit information'!$B$33=2,'Audit information'!$H$27,(IF('Audit information'!$B$33=3,'Audit information'!$H$28,(IF('Audit information'!$B$33=4,'Audit information'!$H$29,(IF('Audit information'!$B$33=5,'Audit information'!$H$30,"NCXX")))))))))))),"DELETE ROW") -> NCXX
A40: =IF('Audit information'!$B$36>3,"<<Requirement>>","DELETE ROW") -> <<Requirement>>
A41: =IF('Audit information'!$B$36>3,"<<Evidence>>","DELETE ROW") -> <<Evidence>>
A42: =IF(A41="DELETE ROW","DELETE ROW","")
A43: =IF('Audit information'!$B$36>4,(IF('Audit information'!$B$33=0,'Audit information'!$H$26,(IF('Audit information'!$B$33=1,'Audit information'!$H$27,(IF('Audit information'!$B$33=2,'Audit information'!$H$28,(IF('Audit information'!$B$33=3,'Audit information'!$H$29,(IF('Audit information'!$B$33=4,'Audit information'!$H$30,(IF('Audit information'!$B$33=5,'Audit information'!$H$31,"NCXX")))))))))))),"DELETE ROW") -> NCXX
...
